2021-07-12 14:55:07,967 INFO    MainThread:4228 [internal.py:wandb_internal():91] W&B internal server running at pid: 4228, started at: 2021-07-12 14:55:07.955517
2021-07-12 14:55:07,969 INFO    WriterThread:4228 [datastore.py:open_for_write():80] open: C:\Users\gefre\Desktop\Sezino\ÿ»‘“\SegmentationProject\wandb\run-20210712_145441-254pywwg\run-254pywwg.wandb
2021-07-12 14:55:07,970 DEBUG   HandlerThread:4228 [handler.py:handle_request():124] handle_request: check_version
2021-07-12 14:55:08,010 DEBUG   SenderThread:4228 [sender.py:send():179] send: header
2021-07-12 14:55:08,010 DEBUG   SenderThread:4228 [sender.py:send_request():193] send_request: check_version
2021-07-12 14:55:08,479 DEBUG   SenderThread:4228 [sender.py:send():179] send: run
2021-07-12 14:55:09,233 INFO    SenderThread:4228 [dir_watcher.py:__init__():168] watching files in: C:\Users\gefre\Desktop\Sezino\ÿ»‘“\SegmentationProject\wandb\run-20210712_145441-254pywwg\files
2021-07-12 14:55:09,233 INFO    SenderThread:4228 [sender.py:_start_run_threads():719] run started: 254pywwg with start time 1626076484
2021-07-12 14:56:46,029 ERROR   FileStreamThread:4228 [file_stream.py:_thread_except_body():311] generic exception in filestream thread
Traceback (most recent call last):
  File "C:\Users\gefre\anaconda3\envs\env\lib\site-packages\wandb\sdk\internal\file_stream.py", line 307, in _thread_except_body
    self._thread_body()
  File "C:\Users\gefre\anaconda3\envs\env\lib\site-packages\wandb\sdk\internal\file_stream.py", line 288, in _thread_body
    "uploaded": list(uploaded),
  File "C:\Users\gefre\anaconda3\envs\env\lib\site-packages\wandb\sdk\internal\file_stream.py", line 320, in _handle_response
    raise response
  File "C:\Users\gefre\anaconda3\envs\env\lib\site-packages\wandb\sdk\internal\file_stream.py", line 419, in request_with_retry
    response.raise_for_status()
  File "C:\Users\gefre\AppData\Roaming\Python\Python37\site-packages\requests\models.py", line 943, in raise_for_status
    raise HTTPError(http_error_msg, response=self)
requests.exceptions.HTTPError: 404 Client Error: Not Found for url: https://api.wandb.ai/files/emorh/segmentation%20project/254pywwg/file_stream
2021-07-13 06:51:01,193 WARNING MainThread:4228 [internal.py:is_dead():367] Internal process exiting, parent pid 4404 disappeared
2021-07-13 06:51:05,099 ERROR   MainThread:4228 [internal.py:wandb_internal():143] Internal process shutdown.
2021-07-13 06:51:08,748 INFO    WriterThread:4228 [datastore.py:close():288] close: C:\Users\gefre\Desktop\Sezino\ÿ»‘“\SegmentationProject\wandb\run-20210712_145441-254pywwg\run-254pywwg.wandb
2021-07-13 06:51:09,714 INFO    HandlerThread:4228 [handler.py:finish():638] shutting down handler
2021-07-13 06:51:10,248 INFO    SenderThread:4228 [sender.py:finish():945] shutting down sender
2021-07-13 06:51:11,094 INFO    SenderThread:4228 [dir_watcher.py:finish():282] shutting down directory watcher
2021-07-13 06:51:11,326 INFO    SenderThread:4228 [dir_watcher.py:finish():312] scan: C:\Users\gefre\Desktop\Sezino\ÿ»‘“\SegmentationProject\wandb\run-20210712_145441-254pywwg\files
2021-07-13 06:51:11,568 INFO    SenderThread:4228 [dir_watcher.py:finish():318] scan save: C:\Users\gefre\Desktop\Sezino\ÿ»‘“\SegmentationProject\wandb\run-20210712_145441-254pywwg\files\config.yaml config.yaml
2021-07-13 06:51:13,173 INFO    SenderThread:4228 [file_pusher.py:finish():177] shutting down file pusher
2021-07-13 06:51:13,689 INFO    SenderThread:4228 [file_pusher.py:join():182] waiting for file pusher
2021-07-13 06:51:25,238 ERROR   SenderThread:4228 [file_stream.py:finish():395] FileStream exception
Traceback (most recent call last):
  File "C:\Users\gefre\anaconda3\envs\env\lib\site-packages\wandb\sdk\internal\file_stream.py", line 307, in _thread_except_body
    self._thread_body()
  File "C:\Users\gefre\anaconda3\envs\env\lib\site-packages\wandb\sdk\internal\file_stream.py", line 288, in _thread_body
    "uploaded": list(uploaded),
  File "C:\Users\gefre\anaconda3\envs\env\lib\site-packages\wandb\sdk\internal\file_stream.py", line 320, in _handle_response
    raise response
  File "C:\Users\gefre\anaconda3\envs\env\lib\site-packages\wandb\sdk\internal\file_stream.py", line 419, in request_with_retry
    response.raise_for_status()
  File "C:\Users\gefre\AppData\Roaming\Python\Python37\site-packages\requests\models.py", line 943, in raise_for_status
    raise HTTPError(http_error_msg, response=self)
requests.exceptions.HTTPError: 404 Client Error: Not Found for url: https://api.wandb.ai/files/emorh/segmentation%20project/254pywwg/file_stream
2021-07-13 06:51:25,269 ERROR   MainThread:4228 [internal.py:wandb_internal():159] Thread SenderThread:
Traceback (most recent call last):
  File "C:\Users\gefre\anaconda3\envs\env\lib\site-packages\wandb\sdk\internal\internal_util.py", line 55, in run
    self._run()
  File "C:\Users\gefre\anaconda3\envs\env\lib\site-packages\wandb\sdk\internal\internal_util.py", line 106, in _run
    self._finish()
  File "C:\Users\gefre\anaconda3\envs\env\lib\site-packages\wandb\sdk\internal\internal.py", line 295, in _finish
    self._sm.finish()
  File "C:\Users\gefre\anaconda3\envs\env\lib\site-packages\wandb\sdk\internal\sender.py", line 956, in finish
    self._fs.finish(self._exit_code)
  File "C:\Users\gefre\anaconda3\envs\env\lib\site-packages\wandb\sdk\internal\file_stream.py", line 397, in finish
    six.reraise(*self._exc_info)
  File "C:\Users\gefre\anaconda3\envs\env\lib\site-packages\six.py", line 702, in reraise
    raise value.with_traceback(tb)
  File "C:\Users\gefre\anaconda3\envs\env\lib\site-packages\wandb\sdk\internal\file_stream.py", line 307, in _thread_except_body
    self._thread_body()
  File "C:\Users\gefre\anaconda3\envs\env\lib\site-packages\wandb\sdk\internal\file_stream.py", line 288, in _thread_body
    "uploaded": list(uploaded),
  File "C:\Users\gefre\anaconda3\envs\env\lib\site-packages\wandb\sdk\internal\file_stream.py", line 320, in _handle_response
    raise response
  File "C:\Users\gefre\anaconda3\envs\env\lib\site-packages\wandb\sdk\internal\file_stream.py", line 419, in request_with_retry
    response.raise_for_status()
  File "C:\Users\gefre\AppData\Roaming\Python\Python37\site-packages\requests\models.py", line 943, in raise_for_status
    raise HTTPError(http_error_msg, response=self)
requests.exceptions.HTTPError: 404 Client Error: Not Found for url: https://api.wandb.ai/files/emorh/segmentation%20project/254pywwg/file_stream
2021-07-13 06:51:28,645 INFO    MainThread:4228 [internal.py:handle_exit():78] Internal process exited
